<?xml version="1.0" ?>
<robot name="zau" version="1.0">
  <material name="aluminum">
    <color rgba="0.5 0.5 0.5 1.0"/>
  </material>
  <material name="plastic">
    <color rgba="0.1 0.1 0.1 1.0"/>
  </material>
  <material name="dark">
    <color rgba="0.3 0.3 0.3 1.0"/>
  </material>
  <material name="light_black">
    <color rgba="0.4 0.4 0.4 1.0"/>
  </material>
  <gazebo reference="base_link_mb">
    <sensor name="base_link_mb" type="contact">
      <update_rate>1000.0</update_rate>
      <always_on>true</always_on>
      <contact>
        <collision>base_footprint_fixed_joint_lump__base_link_collision</collision>
      </contact>
      <plugin filename="libgazebo_ros_bumper.so" name="base_link_contact_sensor_plugin">
        <bumperTopicName>contact</bumperTopicName>
        <frameName>world</frameName>
      </plugin>
    </sensor>
  </gazebo>
  <gazebo reference="base_link_mb">
    <material>Gazebo/DarkGrey</material>
  </gazebo>
  <gazebo reference="wheel_left_link">
    <mu1 value="1.0"/>
    <mu2 value="1.0"/>
    <kp value="10000000.0"/>
    <kd value="1.0"/>
    <minDepth>0.001</minDepth>
    <maxVel>0.1</maxVel>
    <fdir1>1 0 0</fdir1>
    <material>Gazebo/FlatBlack</material>
  </gazebo>
  <gazebo reference="wheel_right_link">
    <mu1 value="1.0"/>
    <mu2 value="1.0"/>
    <kp value="10000000.0"/>
    <kd value="1.0"/>
    <minDepth>0.001</minDepth>
    <maxVel>0.1</maxVel>
    <fdir1>1 0 0</fdir1>
    <material>Gazebo/FlatBlack</material>
  </gazebo>
  <gazebo reference="caster_back_right_link">
    <mu1>0.1</mu1>
    <mu2>0.1</mu2>
    <kp>1000000.0</kp>
    <kd>100.0</kd>
    <minDepth>0.001</minDepth>
    <maxVel>1.0</maxVel>
    <material>Gazebo/FlatBlack</material>
  </gazebo>
  <gazebo reference="caster_back_left_link">
    <mu1>0.1</mu1>
    <mu2>0.1</mu2>
    <kp>1000000.0</kp>
    <kd>100.0</kd>
    <minDepth>0.001</minDepth>
    <maxVel>1.0</maxVel>
    <material>Gazebo/FlatBlack</material>
  </gazebo>
  <gazebo reference="caster_front_right_link">
    <mu1>0.1</mu1>
    <mu2>0.1</mu2>
    <kp>1000000.0</kp>
    <kd>100.0</kd>
    <minDepth>0.001</minDepth>
    <maxVel>1.0</maxVel>
    <material>Gazebo/FlatBlack</material>
  </gazebo>
  <gazebo reference="caster_front_left_link">
    <mu1>0.1</mu1>
    <mu2>0.1</mu2>
    <kp>1000000.0</kp>
    <kd>100.0</kd>
    <minDepth>0.001</minDepth>
    <maxVel>1.0</maxVel>
    <material>Gazebo/FlatBlack</material>
  </gazebo>
  <gazebo reference="imu_link">
    <sensor name="imu" type="imu">
      <always_on>true</always_on>
      <visualize>false</visualize>
    </sensor>
    <material>Gazebo/Grey</material>
  </gazebo>
  <gazebo>
    <plugin filename="libgazebo_ros_diff_drive.so" name="moving_base_controller">
      <commandTopic>cmd_vel</commandTopic>
      <odometryTopic>odom</odometryTopic>
      <odometryFrame>odom</odometryFrame>
      <odometrySource>world</odometrySource>
      <publishOdomTF>true</publishOdomTF>
      <robotBaseFrame>base_footprint</robotBaseFrame>
      <publishWheelTF>false</publishWheelTF>
      <publishTf>true</publishTf>
      <publishWheelJointState>true</publishWheelJointState>
      <legacyMode>false</legacyMode>
      <updateRate>30</updateRate>
      <leftJoint>wheel_left_joint</leftJoint>
      <rightJoint>wheel_right_joint</rightJoint>
      <wheelSeparation>0.650</wheelSeparation>
      <wheelDiameter>0.168</wheelDiameter>
      <wheelAcceleration>1</wheelAcceleration>
      <wheelTorque>50</wheelTorque>
      <rosDebugLevel>na</rosDebugLevel>
    </plugin>
  </gazebo>
  <gazebo>
    <plugin filename="libgazebo_ros_imu.so" name="imu_plugin">
      <alwaysOn>true</alwaysOn>
      <bodyName>imu_link</bodyName>
      <frameName>imu_link</frameName>
      <topicName>imu</topicName>
      <serviceName>imu_service</serviceName>
      <gaussianNoise>0.0</gaussianNoise>
      <updateRate>0</updateRate>
      <imu>
        <noise>
          <type>gaussian</type>
          <rate>
            <mean>0.0</mean>
            <stddev>2e-4</stddev>
            <bias_mean>0.0000075</bias_mean>
            <bias_stddev>0.0000008</bias_stddev>
          </rate>
          <accel>
            <mean>0.0</mean>
            <stddev>1.7e-2</stddev>
            <bias_mean>0.1</bias_mean>
            <bias_stddev>0.001</bias_stddev>
          </accel>
        </noise>
      </imu>
    </plugin>
  </gazebo>
  <gazebo reference="base_scan_front">
    <material>Gazebo/DarkGrey</material>
    <sensor name="lds_lfcd_sensor_front" type="ray">
      <pose>0 0 0 0 0 0</pose>
      <visualize>true</visualize>
      <update_rate>5</update_rate>
      <ray>
        <scan>
          <horizontal>
            <samples>360</samples>
            <resolution>1</resolution>
            <min_angle>0</min_angle>
            <max_angle>4.71</max_angle>
          </horizontal>
        </scan>
        <range>
          <min>0.120</min>
          <max>3.5</max>
          <resolution>0.015</resolution>
        </range>
        <noise>
          <type>gaussian</type>
          <mean>0.0</mean>
          <stddev>0.01</stddev>
        </noise>
      </ray>
      <plugin filename="libgazebo_ros_laser.so" name="gazebo_ros_lds_lfcd_controller">
        <topicName>laser/scan_front</topicName>
        <frameName>base_scan_front</frameName>
      </plugin>
    </sensor>
  </gazebo>
  <gazebo reference="base_scan_back">
    <material>Gazebo/DarkGrey</material>
    <sensor name="lds_lfcd_sensor_back" type="ray">
      <pose>0 0 0 0 0 0</pose>
      <visualize>true</visualize>
      <update_rate>5</update_rate>
      <ray>
        <scan>
          <horizontal>
            <samples>360</samples>
            <resolution>1</resolution>
            <min_angle>0</min_angle>
            <max_angle>4.71</max_angle>
          </horizontal>
        </scan>
        <range>
          <min>0.120</min>
          <max>3.5</max>
          <resolution>0.015</resolution>
        </range>
        <noise>
          <type>gaussian</type>
          <mean>0.0</mean>
          <stddev>0.01</stddev>
        </noise>
      </ray>
      <plugin filename="libgazebo_ros_laser.so" name="gazebo_ros_lds_lfcd_controller">
        <topicName>laser/scan_back</topicName>
        <frameName>base_scan_back</frameName>
      </plugin>
    </sensor>
  </gazebo>
  <joint name="lidar_body_base_mount_joint" type="fixed">
    <origin xyz="0.42 0.0 0.785" rpy="0.0 0.0 0.0"/>
    <parent link="base_link_mb"/>
    <child link="lidar_body_base_link"/>
  </joint>
  <link name="lidar_body_base_link">
    <inertial>
      <origin xyz="0.0 0.0 0.03585" rpy="0 0 0"/>
      <mass value="0.83"/>
      <inertia ixx="0.000908059425" ixy="0.0" ixz="0.0" iyy="0.000908059425" iyz="0.0" izz="0.0011049624"/>
    </inertial>
    <visual>
      <geometry>
        <mesh filename="package://velodyne_description/meshes/VLP16_base_1.dae"/>
      </geometry>
    </visual>
    <visual>
      <geometry>
        <mesh filename="package://velodyne_description/meshes/VLP16_base_2.dae"/>
      </geometry>
    </visual>
    <collision>
      <origin xyz="0.0 0.0 0.03585" rpy="0.0 0.0 0.0"/>
      <geometry>
        <cylinder radius="0.0516" length="0.0717"/>
      </geometry>
    </collision>
  </link>
  <joint name="lidar_body_base_scan_joint" type="fixed">
    <origin xyz="0.0 0.0 0.0377" rpy="0.0 0.0 0.0"/>
    <parent link="lidar_body_base_link"/>
    <child link="lidar_body"/>
  </joint>
  <link name="lidar_body">
    <inertial>
      <origin xyz="0.0 0.0 0.0" rpy="0 0 0"/>
      <mass value="0.01"/>
      <inertia ixx="1e-07" ixy="0.0" ixz="0.0" iyy="1e-07" iyz="0.0" izz="1e-07"/>
    </inertial>
    <visual>
      <origin xyz="0.0 0.0 -0.0377" rpy="0 0 0"/>
      <geometry>
        <mesh filename="package://velodyne_description/meshes/VLP16_scan.dae"/>
      </geometry>
    </visual>
    <collision>
      <geometry>
        <sphere radius="0.0"/>
      </geometry>
    </collision>
  </link>
  <gazebo reference="lidar_body">
    <sensor name="lidar_body-VLP16" type="gpu_ray">
      <pose>0 0 0 0 0 0</pose>
      <visualize>false</visualize>
      <update_rate>10</update_rate>
      <ray>
        <scan>
          <horizontal>
            <samples>440</samples>
            <resolution>1</resolution>
            <min_angle>-3.141592653589793</min_angle>
            <max_angle>3.141592653589793</max_angle>
          </horizontal>
          <vertical>
            <samples>16</samples>
            <resolution>1</resolution>
            <min_angle>-0.2617993877991494</min_angle>
            <max_angle> 0.2617993877991494</max_angle>
          </vertical>
        </scan>
        <range>
          <min>0.3</min>
          <max>131.0</max>
          <resolution>0.001</resolution>
        </range>
        <noise>
          <type>gaussian</type>
          <mean>0.0</mean>
          <stddev>0.0</stddev>
        </noise>
      </ray>
      <plugin filename="libgazebo_ros_velodyne_gpu_laser.so" name="gazebo_ros_laser_controller">
        <topicName>/velodyne_points</topicName>
        <frameName>lidar_body</frameName>
        <organize_cloud>False</organize_cloud>
        <min_range>0.9</min_range>
        <max_range>130.0</max_range>
        <gaussianNoise>0.008</gaussianNoise>
      </plugin>
    </sensor>
  </gazebo>
  <joint name="rgb_body_right_joint" type="fixed">
    <origin xyz="0.42 -0.18 0.785" rpy="0.0 0.0 -0.7853981633974483"/>
    <parent link="base_link_mb"/>
    <child link="rgb_body_right_link"/>
  </joint>
  <link name="rgb_body_right_link">
    <inertial>
      <origin xyz="0.0 0.0 0.0" rpy="0 0 0"/>
      <mass value="0.00564"/>
      <inertia ixx="0.003881243" ixy="0.0" ixz="0.0" iyy="0.00049894" iyz="0.0" izz="0.003879257"/>
    </inertial>
    <visual>
      <origin xyz="0.0 0.0 0.0" rpy="0.0 0.0 0.0"/>
      <geometry>
        <mesh filename="package://rrbot_description/meshes/rgb_camera/rgb_camera.stl" scale="1.0 1.0 1.0"/>
      </geometry>
      <material name="red">
        <color rgba="0.9 0.0 0.0 1.0"/>
      </material>
    </visual>
    <collision>
      <origin xyz="0.0 0.0 0.0" rpy="0.0 0.0 0.0"/>
      <geometry>
        <mesh filename="package://rrbot_description/meshes/rgb_camera/rgb_camera.stl" scale="1.0 1.0 1.0"/>
      </geometry>
    </collision>
  </link>
  <gazebo reference="rgb_body_right_link">
    <selfCollide>false</selfCollide>
    <material>Gazebo/Red</material>
  </gazebo>
  <joint name="rgb_body_right_optical_joint" type="fixed">
    <origin xyz="0.0 0.0 0.0" rpy="-1.5707963267948966 0.0 -1.5707963267948966"/>
    <parent link="rgb_body_right_link"/>
    <child link="rgb_body_right_optical_frame"/>
  </joint>
  <link name="rgb_body_right_optical_frame"/>
  <gazebo reference="rgb_body_right_link">
    <sensor name="camera" type="camera">
      <update_rate>10.0</update_rate>
      <camera>
        <horizontal_fov>1.0471975511965976</horizontal_fov>
        <image>
          <format>B8G8R8</format>
          <width>1200</width>
          <height>800</height>
        </image>
        <clip>
          <near>0.10</near>
          <far>8.0</far>
        </clip>
      </camera>
      <plugin filename="libgazebo_ros_camera.so" name="rgb_body_right_rgb_camera_controller">
        <cameraName>rgb_body_right</cameraName>
        <alwaysOn>true</alwaysOn>
        <updateRate>0</updateRate>
        <imageTopicName>image_raw</imageTopicName>
        <cameraInfoTopicName>camera_info</cameraInfoTopicName>
        <frameName>rgb_body_right_optical_frame</frameName>
        <baseline>0.0</baseline>
        <distortion_k1>0.0</distortion_k1>
        <distortion_k2>0.0</distortion_k2>
        <distortion_k3>0.0</distortion_k3>
        <distortion_t1>0.0</distortion_t1>
        <distortion_t2>0.0</distortion_t2>
      </plugin>
    </sensor>
  </gazebo>
  <joint name="rgb_body_left_joint" type="fixed">
    <origin xyz="0.4912921399098926 0.08316541125075634 1.0832106256157366" rpy="2.5553632034074596 0.22645120802730287 -0.3135815114102744"/>
    <parent link="base_link_mb"/>
    <child link="rgb_body_left_link"/>
  </joint>
  <link name="rgb_body_left_link">
    <inertial>
      <origin xyz="0.0 0.0 0.0" rpy="0 0 0"/>
      <mass value="0.00564"/>
      <inertia ixx="0.003881243" ixy="0.0" ixz="0.0" iyy="0.00049894" iyz="0.0" izz="0.003879257"/>
    </inertial>
    <visual>
      <origin xyz="0.0 0.0 0.0" rpy="0.0 0.0 0.0"/>
      <geometry>
        <mesh filename="package://rrbot_description/meshes/rgb_camera/rgb_camera.stl" scale="1.0 1.0 1.0"/>
      </geometry>
      <material name="green">
        <color rgba="0.0 0.9 0.0 1.0"/>
      </material>
    </visual>
    <collision>
      <origin xyz="0.0 0.0 0.0" rpy="0.0 0.0 0.0"/>
      <geometry>
        <mesh filename="package://rrbot_description/meshes/rgb_camera/rgb_camera.stl" scale="1.0 1.0 1.0"/>
      </geometry>
    </collision>
  </link>
  <gazebo reference="rgb_body_left_link">
    <selfCollide>false</selfCollide>
    <material>Gazebo/Green</material>
  </gazebo>
  <joint name="rgb_body_left_optical_joint" type="fixed">
    <origin xyz="0.0 0.0 0.0" rpy="-1.5707963267948966 0.0 -1.5707963267948966"/>
    <parent link="rgb_body_left_link"/>
    <child link="rgb_body_left_optical_frame"/>
  </joint>
  <link name="rgb_body_left_optical_frame"/>
  <gazebo reference="rgb_body_left_link">
    <sensor name="camera" type="camera">
      <update_rate>10.0</update_rate>
      <camera>
        <horizontal_fov>1.0471975511965976</horizontal_fov>
        <image>
          <format>B8G8R8</format>
          <width>1200</width>
          <height>800</height>
        </image>
        <clip>
          <near>0.10</near>
          <far>8.0</far>
        </clip>
      </camera>
      <plugin filename="libgazebo_ros_camera.so" name="rgb_body_left_rgb_camera_controller">
        <cameraName>rgb_body_left</cameraName>
        <alwaysOn>true</alwaysOn>
        <updateRate>0</updateRate>
        <imageTopicName>image_raw</imageTopicName>
        <cameraInfoTopicName>camera_info</cameraInfoTopicName>
        <frameName>rgb_body_left_optical_frame</frameName>
        <baseline>0.0</baseline>
        <distortion_k1>0.0</distortion_k1>
        <distortion_k2>0.0</distortion_k2>
        <distortion_k3>0.0</distortion_k3>
        <distortion_t1>0.0</distortion_t1>
        <distortion_t2>0.0</distortion_t2>
      </plugin>
    </sensor>
  </gazebo>
  <joint name="vo_camera_joint" type="fixed">
    <origin xyz="0.47 0.0 0.75" rpy="0.0 0.0 0.0"/>
    <parent link="base_link_mb"/>
    <child link="vo_camera_link"/>
  </joint>
  <link name="vo_camera_link">
    <inertial>
      <origin xyz="0.0061266 3.8568e-05 -1.9004e-05" rpy="0.0 0.0 0.0"/>
      <mass value="0.030988"/>
      <inertia ixx="3.0221e-05" ixy="-1.6541e-10" ixz="4.8935e-11" iyy="1.9363e-06" iyz="9.2265e-11" izz="2.9002e-05"/>
    </inertial>
    <visual>
      <origin xyz="0.0 0.0 0.0" rpy="0.0 0.0 3.141592653589793"/>
      <geometry>
        <mesh filename="package://zau_description/meshes/sensors/t265.STL"/>
      </geometry>
    </visual>
    <collision>
      <origin xyz="0.0 0.0 0.0" rpy="0.0 0.0 3.141592653589793"/>
      <geometry>
        <mesh filename="package://zau_description/meshes/sensors/t265.STL"/>
      </geometry>
    </collision>
  </link>
  <link name="base_footprint"/>
  <joint name="base_joint" type="fixed">
    <origin xyz="0.0 0.0 0.01" rpy="0.0 0.0 0.0"/>
    <parent link="base_footprint"/>
    <child link="base_link_mb"/>
  </joint>
  <link name="base_link_mb">
    <visual>
      <origin xyz="-0.43 -0.33 0.03" rpy="1.57 0.0 1.57"/>
      <geometry>
        <mesh filename="package://zau_description/meshes/moving_base/moving_base.STL" scale="0.001 0.001 0.001"/>
      </geometry>
      <material name="light_black"/>
    </visual>
    <collision>
      <origin xyz="0.0 0.0 0.459" rpy="0.0 0.0 0.0"/>
      <geometry>
        <box size="0.9 0.6 0.77"/>
      </geometry>
    </collision>
  </link>
  <link name="inertial_link">
    <inertial>
      <origin xyz="-0.00065 -0.085 0.062" rpy="0 0 0"/>
      <mass value="500.0"/>
      <inertia ixx="0.6022" ixy="-0.02364" ixz="-0.1197" iyy="1.7386" iyz="-0.001544" izz="2.0296"/>
    </inertial>
  </link>
  <joint name="inertial_joint" type="fixed">
    <origin xyz="0.0 0.0 0.0" rpy="0.0 0.0 0.0"/>
    <parent link="base_link_mb"/>
    <child link="inertial_link"/>
  </joint>
  <joint name="wheel_left_joint" type="continuous">
    <origin xyz="0.0 0.325 0.074" rpy="-1.57 0.0 0.0"/>
    <axis xyz="0.0 0.0 1.0"/>
    <parent link="base_link_mb"/>
    <child link="wheel_left_link"/>
  </joint>
  <link name="wheel_left_link">
    <inertial>
      <origin xyz="0.0 0.0 0.0" rpy="0 0 0"/>
      <mass value="2.637"/>
      <inertia ixx="0.02467" ixy="0.0" ixz="0.0" iyy="0.04411" iyz="0.0" izz="0.02467"/>
    </inertial>
    <visual>
      <origin xyz="0.0 0.0 -0.055" rpy="-1.57 0.0 0.0"/>
      <geometry>
        <mesh filename="package://zau_description/meshes/robot_wheels/left_tire.stl" scale="0.0025 0.0025 0.0025"/>
      </geometry>
      <material name="dark"/>
    </visual>
    <collision>
      <origin xyz="0.0 0.0 0.0" rpy="0.0 0.0 0.0"/>
      <geometry>
        <cylinder radius="0.084" length="0.044"/>
      </geometry>
    </collision>
  </link>
  <joint name="wheel_right_joint" type="continuous">
    <origin xyz="0.0 -0.325 0.074" rpy="-1.57 0.0 0.0"/>
    <axis xyz="0.0 0.0 1.0"/>
    <parent link="base_link_mb"/>
    <child link="wheel_right_link"/>
  </joint>
  <link name="wheel_right_link">
    <inertial>
      <origin xyz="0.0 0.0 0.0" rpy="0 0 0"/>
      <mass value="2.637"/>
      <inertia ixx="0.02467" ixy="0.0" ixz="0.0" iyy="0.04411" iyz="0.0" izz="0.02467"/>
    </inertial>
    <visual>
      <origin xyz="0.0 0.0 0.055" rpy="1.57 0.0 0.0"/>
      <geometry>
        <mesh filename="package://zau_description/meshes/robot_wheels/left_tire.stl" scale="0.0025 0.0025 0.0025"/>
      </geometry>
      <material name="dark"/>
    </visual>
    <collision>
      <origin xyz="0.0 0.0 0.0" rpy="0.0 0.0 0.0"/>
      <geometry>
        <cylinder radius="0.084" length="0.044"/>
      </geometry>
    </collision>
  </link>
  <joint name="caster_back_right_joint" type="fixed">
    <origin xyz="-0.345 -0.19 -0.004" rpy="-1.57 0.0 0.0"/>
    <parent link="base_link_mb"/>
    <child link="caster_back_right_link"/>
  </joint>
  <link name="caster_back_right_link">
    <inertial>
      <origin xyz="0.0 0.0 0.0" rpy="0 0 0"/>
      <mass value="0.005"/>
      <inertia ixx="0.001" ixy="0.0" ixz="0.0" iyy="0.001" iyz="0.0" izz="0.001"/>
    </inertial>
    <visual>
      <origin xyz="0.027 -0.06 0.0" rpy="1.57 0.0 0.0"/>
      <geometry>
        <mesh filename="package://zau_description/meshes/robot_wheels/left_tire.stl" scale="0.002 0.002 0.002"/>
      </geometry>
      <material name="dark"/>
    </visual>
    <collision>
      <origin xyz="0.0 0.001 0.0" rpy="0.0 0.0 0.0"/>
      <geometry>
        <box size="0.03 0.009 0.078"/>
      </geometry>
    </collision>
  </link>
  <joint name="caster_back_left_joint" type="fixed">
    <origin xyz="-0.345 0.19 -0.004" rpy="-1.57 0.0 0.0"/>
    <parent link="base_link_mb"/>
    <child link="caster_back_left_link"/>
  </joint>
  <link name="caster_back_left_link">
    <inertial>
      <origin xyz="0.0 0.0 0.0" rpy="0 0 0"/>
      <mass value="0.005"/>
      <inertia ixx="0.001" ixy="0.0" ixz="0.0" iyy="0.001" iyz="0.0" izz="0.001"/>
    </inertial>
    <visual>
      <origin xyz="0.027 -0.06 0.0" rpy="-1.57 0.0 0.0"/>
      <geometry>
        <mesh filename="package://zau_description/meshes/robot_wheels/left_tire.stl" scale="0.002 0.002 0.002"/>
      </geometry>
      <material name="dark"/>
    </visual>
    <collision>
      <origin xyz="0.0 0.001 0.0" rpy="0.0 0.0 0.0"/>
      <geometry>
        <box size="0.03 0.009 0.078"/>
      </geometry>
    </collision>
  </link>
  <joint name="caster_front_right_joint" type="fixed">
    <origin xyz="0.345 -0.19 -0.004" rpy="-1.57 0.0 0.0"/>
    <parent link="base_link_mb"/>
    <child link="caster_front_right_link"/>
  </joint>
  <link name="caster_front_right_link">
    <inertial>
      <origin xyz="0.0 0.0 0.0" rpy="0 0 0"/>
      <mass value="0.005"/>
      <inertia ixx="0.001" ixy="0.0" ixz="0.0" iyy="0.001" iyz="0.0" izz="0.001"/>
    </inertial>
    <visual>
      <origin xyz="0.0 -0.06 0.0" rpy="1.57 0.0 0.0"/>
      <geometry>
        <mesh filename="package://zau_description/meshes/robot_wheels/left_tire.stl" scale="0.002 0.002 0.002"/>
      </geometry>
      <material name="dark"/>
    </visual>
    <collision>
      <origin xyz="0.0 0.001 0.0" rpy="0.0 0.0 0.0"/>
      <geometry>
        <box size="0.03 0.009 0.078"/>
      </geometry>
    </collision>
  </link>
  <joint name="caster_front_left_joint" type="fixed">
    <origin xyz="0.345 0.19 -0.004" rpy="-1.57 0.0 0.0"/>
    <parent link="base_link_mb"/>
    <child link="caster_front_left_link"/>
  </joint>
  <link name="caster_front_left_link">
    <inertial>
      <origin xyz="0.0 0.0 0.0" rpy="0 0 0"/>
      <mass value="0.005"/>
      <inertia ixx="0.001" ixy="0.0" ixz="0.0" iyy="0.001" iyz="0.0" izz="0.001"/>
    </inertial>
    <visual>
      <origin xyz="0.0 -0.06 0.0" rpy="-1.57 0.0 0.0"/>
      <geometry>
        <mesh filename="package://zau_description/meshes/robot_wheels/left_tire.stl" scale="0.002 0.002 0.002"/>
      </geometry>
      <material name="dark"/>
    </visual>
    <collision>
      <origin xyz="0.0 0.001 0.0" rpy="0.0 0.0 0.0"/>
      <geometry>
        <box size="0.03 0.009 0.078"/>
      </geometry>
    </collision>
  </link>
  <joint name="imu_joint" type="fixed">
    <origin xyz="0.0 0.0 0.068" rpy="0.0 0.0 0.0"/>
    <parent link="base_link_mb"/>
    <child link="imu_link"/>
  </joint>
  <link name="imu_link"/>
  <joint name="scan_joint_front" type="fixed">
    <origin xyz="-0.45 0.3 0.18" rpy="0.0 0.0 0.0"/>
    <parent link="base_link_mb"/>
    <child link="base_scan_front"/>
  </joint>
  <link name="base_scan_front">
    <inertial>
      <origin xyz="0.0 0.0 0.0" rpy="0 0 0"/>
      <mass value="0.114"/>
      <inertia ixx="0.001" ixy="0.0" ixz="0.0" iyy="0.001" iyz="0.0" izz="0.001"/>
    </inertial>
    <collision>
      <origin xyz="0.015 0.0 -0.0065" rpy="0.0 0.0 0.0"/>
      <geometry>
        <cylinder radius="0.055" length="0.0315"/>
      </geometry>
    </collision>
  </link>
  <joint name="scan_joint_back" type="fixed">
    <origin xyz="0.5 -0.3 0.18" rpy="0.0 0.0 -3.14"/>
    <parent link="base_link_mb"/>
    <child link="base_scan_back"/>
  </joint>
  <link name="base_scan_back">
    <inertial>
      <origin xyz="0.0 0.0 0.0" rpy="0 0 0"/>
      <mass value="0.114"/>
      <inertia ixx="0.001" ixy="0.0" ixz="0.0" iyy="0.001" iyz="0.0" izz="0.001"/>
    </inertial>
    <collision>
      <origin xyz="0.015 0.0 -0.0065" rpy="0.0 0.0 0.0"/>
      <geometry>
        <cylinder radius="0.055" length="0.0315"/>
      </geometry>
    </collision>
  </link>
  <transmission name="shoulder_pan_trans">
    <type>transmission_interface/SimpleTransmission</type>
    <joint name="shoulder_pan_joint">
      <hardwareInterface>hardware_interface/PositionJointInterface</hardwareInterface>
    </joint>
    <actuator name="shoulder_pan_motor">
      <mechanicalReduction>1.0</mechanicalReduction>
    </actuator>
  </transmission>
  <transmission name="shoulder_lift_trans">
    <type>transmission_interface/SimpleTransmission</type>
    <joint name="shoulder_lift_joint">
      <hardwareInterface>hardware_interface/PositionJointInterface</hardwareInterface>
    </joint>
    <actuator name="shoulder_lift_motor">
      <mechanicalReduction>1.0</mechanicalReduction>
    </actuator>
  </transmission>
  <transmission name="elbow_trans">
    <type>transmission_interface/SimpleTransmission</type>
    <joint name="elbow_joint">
      <hardwareInterface>hardware_interface/PositionJointInterface</hardwareInterface>
    </joint>
    <actuator name="elbow_motor">
      <mechanicalReduction>1.0</mechanicalReduction>
    </actuator>
  </transmission>
  <transmission name="wrist_1_trans">
    <type>transmission_interface/SimpleTransmission</type>
    <joint name="wrist_1_joint">
      <hardwareInterface>hardware_interface/PositionJointInterface</hardwareInterface>
    </joint>
    <actuator name="wrist_1_motor">
      <mechanicalReduction>1.0</mechanicalReduction>
    </actuator>
  </transmission>
  <transmission name="wrist_2_trans">
    <type>transmission_interface/SimpleTransmission</type>
    <joint name="wrist_2_joint">
      <hardwareInterface>hardware_interface/PositionJointInterface</hardwareInterface>
    </joint>
    <actuator name="wrist_2_motor">
      <mechanicalReduction>1.0</mechanicalReduction>
    </actuator>
  </transmission>
  <transmission name="wrist_3_trans">
    <type>transmission_interface/SimpleTransmission</type>
    <joint name="wrist_3_joint">
      <hardwareInterface>hardware_interface/PositionJointInterface</hardwareInterface>
    </joint>
    <actuator name="wrist_3_motor">
      <mechanicalReduction>1.0</mechanicalReduction>
    </actuator>
  </transmission>
  <link name="base_link"/>
  <link name="base_link_inertia">
    <inertial>
      <origin xyz="0.0 0.0 0.0" rpy="0.0 0.0 0.0"/>
      <mass value="4.0"/>
      <inertia ixx="0.00443333156" ixy="0.0" ixz="0.0" iyy="0.00443333156" iyz="0.0" izz="0.0072"/>
    </inertial>
    <visual>
      <origin xyz="0.0 0.0 0.0" rpy="0.0 0.0 3.141592653589793"/>
      <geometry>
        <mesh filename="package://ur_description/meshes/ur5/visual/base.dae"/>
      </geometry>
      <material name="LightGrey">
        <color rgba="0.7 0.7 0.7 1.0"/>
      </material>
    </visual>
    <collision>
      <origin xyz="0.0 0.0 0.0" rpy="0.0 0.0 3.141592653589793"/>
      <geometry>
        <mesh filename="package://ur_description/meshes/ur5/collision/base.stl"/>
      </geometry>
    </collision>
  </link>
  <link name="shoulder_link">
    <inertial>
      <origin xyz="0.0 0.0 0.0" rpy="0.0 0.0 0.0"/>
      <mass value="3.7"/>
      <inertia ixx="0.014972352344389999" ixy="0.0" ixz="0.0" iyy="0.014972352344389999" iyz="0.0" izz="0.01040625"/>
    </inertial>
    <visual>
      <origin xyz="0.0 0.0 0.0" rpy="0.0 0.0 3.141592653589793"/>
      <geometry>
        <mesh filename="package://ur_description/meshes/ur5/visual/shoulder.dae"/>
      </geometry>
      <material name="LightGrey">
        <color rgba="0.7 0.7 0.7 1.0"/>
      </material>
    </visual>
    <collision>
      <origin xyz="0.0 0.0 0.0" rpy="0.0 0.0 3.141592653589793"/>
      <geometry>
        <mesh filename="package://ur_description/meshes/ur5/collision/shoulder.stl"/>
      </geometry>
    </collision>
  </link>
  <link name="upper_arm_link">
    <inertial>
      <origin xyz="-0.2125 0.0 0.136" rpy="0.0 1.5707963267948966 0.0"/>
      <mass value="8.393"/>
      <inertia ixx="0.1338857818623325" ixy="0.0" ixz="0.0" iyy="0.1338857818623325" iyz="0.0" izz="0.0151074"/>
    </inertial>
    <visual>
      <origin xyz="0.0 0.0 0.13585" rpy="1.5707963267948966 0.0 -1.5707963267948966"/>
      <geometry>
        <mesh filename="package://ur_description/meshes/ur5/visual/upperarm.dae"/>
      </geometry>
      <material name="LightGrey">
        <color rgba="0.7 0.7 0.7 1.0"/>
      </material>
    </visual>
    <collision>
      <origin xyz="0.0 0.0 0.13585" rpy="1.5707963267948966 0.0 -1.5707963267948966"/>
      <geometry>
        <mesh filename="package://ur_description/meshes/ur5/collision/upperarm.stl"/>
      </geometry>
    </collision>
  </link>
  <link name="forearm_link">
    <inertial>
      <origin xyz="-0.196125 0.0 0.0165" rpy="0.0 1.5707963267948966 0.0"/>
      <mass value="2.275"/>
      <inertia ixx="0.03121679102890359" ixy="0.0" ixz="0.0" iyy="0.03121679102890359" iyz="0.0" izz="0.004095"/>
    </inertial>
    <visual>
      <origin xyz="0.0 0.0 0.0165" rpy="1.5707963267948966 0.0 -1.5707963267948966"/>
      <geometry>
        <mesh filename="package://ur_description/meshes/ur5/visual/forearm.dae"/>
      </geometry>
      <material name="LightGrey">
        <color rgba="0.7 0.7 0.7 1.0"/>
      </material>
    </visual>
    <collision>
      <origin xyz="0.0 0.0 0.0165" rpy="1.5707963267948966 0.0 -1.5707963267948966"/>
      <geometry>
        <mesh filename="package://ur_description/meshes/ur5/collision/forearm.stl"/>
      </geometry>
    </collision>
  </link>
  <link name="wrist_1_link">
    <inertial>
      <origin xyz="0.0 0.0 0.0" rpy="0.0 0.0 0.0"/>
      <mass value="1.219"/>
      <inertia ixx="0.0020138887777775" ixy="0.0" ixz="0.0" iyy="0.0020138887777775" iyz="0.0" izz="0.0021942"/>
    </inertial>
    <visual>
      <origin xyz="0.0 0.0 -0.093" rpy="1.5707963267948966 0.0 0.0"/>
      <geometry>
        <mesh filename="package://ur_description/meshes/ur5/visual/wrist1.dae"/>
      </geometry>
      <material name="LightGrey">
        <color rgba="0.7 0.7 0.7 1.0"/>
      </material>
    </visual>
    <collision>
      <origin xyz="0.0 0.0 -0.093" rpy="1.5707963267948966 0.0 0.0"/>
      <geometry>
        <mesh filename="package://ur_description/meshes/ur5/collision/wrist1.stl"/>
      </geometry>
    </collision>
  </link>
  <link name="wrist_2_link">
    <inertial>
      <origin xyz="0.0 0.0 0.0" rpy="0.0 0.0 0.0"/>
      <mass value="1.219"/>
      <inertia ixx="0.0018310388509175" ixy="0.0" ixz="0.0" iyy="0.0018310388509175" iyz="0.0" izz="0.0021942"/>
    </inertial>
    <visual>
      <origin xyz="0.0 0.0 -0.095" rpy="0.0 0.0 0.0"/>
      <geometry>
        <mesh filename="package://ur_description/meshes/ur5/visual/wrist2.dae"/>
      </geometry>
      <material name="LightGrey">
        <color rgba="0.7 0.7 0.7 1.0"/>
      </material>
    </visual>
    <collision>
      <origin xyz="0.0 0.0 -0.095" rpy="0.0 0.0 0.0"/>
      <geometry>
        <mesh filename="package://ur_description/meshes/ur5/collision/wrist2.stl"/>
      </geometry>
    </collision>
  </link>
  <link name="wrist_3_link">
    <inertial>
      <origin xyz="0.0 0.0 -0.01525" rpy="0.0 0.0 0.0"/>
      <mass value="0.1879"/>
      <inertia ixx="8.062472608343e-05" ixy="0.0" ixz="0.0" iyy="8.062472608343e-05" iyz="0.0" izz="0.0001321171875"/>
    </inertial>
    <visual>
      <origin xyz="0.0 0.0 -0.0818" rpy="1.5707963267948966 0.0 0.0"/>
      <geometry>
        <mesh filename="package://ur_description/meshes/ur5/visual/wrist3.dae"/>
      </geometry>
      <material name="LightGrey">
        <color rgba="0.7 0.7 0.7 1.0"/>
      </material>
    </visual>
    <collision>
      <origin xyz="0.0 0.0 -0.0818" rpy="1.5707963267948966 0.0 0.0"/>
      <geometry>
        <mesh filename="package://ur_description/meshes/ur5/collision/wrist3.stl"/>
      </geometry>
    </collision>
  </link>
  <joint name="base_link-base_link_inertia" type="fixed">
    <origin xyz="0.0 0.0 0.0" rpy="0.0 0.0 3.141592653589793"/>
    <parent link="base_link"/>
    <child link="base_link_inertia"/>
  </joint>
  <joint name="shoulder_pan_joint" type="revolute">
    <origin xyz="0.0 0.0 0.089159" rpy="0.0 0.0 0.0"/>
    <axis xyz="0.0 0.0 1.0"/>
    <parent link="base_link_inertia"/>
    <child link="shoulder_link"/>
    <limit effort="150.0" lower="-6.283185307179586" upper="6.283185307179586" velocity="3.141592653589793"/>
    <dynamics damping="0.0" friction="0.0"/>
  </joint>
  <joint name="shoulder_lift_joint" type="revolute">
    <origin xyz="0.0 0.0 0.0" rpy="1.570796327 0.0 0.0"/>
    <axis xyz="0.0 0.0 1.0"/>
    <parent link="shoulder_link"/>
    <child link="upper_arm_link"/>
    <limit effort="150.0" lower="-6.283185307179586" upper="6.283185307179586" velocity="3.141592653589793"/>
    <dynamics damping="0.0" friction="0.0"/>
  </joint>
  <joint name="elbow_joint" type="revolute">
    <origin xyz="-0.425 0.0 0.0" rpy="0.0 0.0 0.0"/>
    <axis xyz="0.0 0.0 1.0"/>
    <parent link="upper_arm_link"/>
    <child link="forearm_link"/>
    <limit effort="150.0" lower="-3.141592653589793" upper="3.141592653589793" velocity="3.141592653589793"/>
    <dynamics damping="0.0" friction="0.0"/>
  </joint>
  <joint name="wrist_1_joint" type="revolute">
    <origin xyz="-0.39225 0.0 0.10915" rpy="0.0 0.0 0.0"/>
    <axis xyz="0.0 0.0 1.0"/>
    <parent link="forearm_link"/>
    <child link="wrist_1_link"/>
    <limit effort="28.0" lower="-6.283185307179586" upper="6.283185307179586" velocity="3.141592653589793"/>
    <dynamics damping="0.0" friction="0.0"/>
  </joint>
  <joint name="wrist_2_joint" type="revolute">
    <origin xyz="0.0 -0.09465 -1.941303950897609e-11" rpy="1.570796327 0.0 0.0"/>
    <axis xyz="0.0 0.0 1.0"/>
    <parent link="wrist_1_link"/>
    <child link="wrist_2_link"/>
    <limit effort="28.0" lower="-6.283185307179586" upper="6.283185307179586" velocity="3.141592653589793"/>
    <dynamics damping="0.0" friction="0.0"/>
  </joint>
  <joint name="wrist_3_joint" type="revolute">
    <origin xyz="0.0 0.0823 -1.688001216681175e-11" rpy="1.570796326589793 3.141592653589793 3.141592653589793"/>
    <axis xyz="0.0 0.0 1.0"/>
    <parent link="wrist_2_link"/>
    <child link="wrist_3_link"/>
    <limit effort="28.0" lower="-6.283185307179586" upper="6.283185307179586" velocity="3.141592653589793"/>
    <dynamics damping="0.0" friction="0.0"/>
  </joint>
  <link name="base"/>
  <joint name="base_link-base_fixed_joint" type="fixed">
    <origin xyz="0.0 0.0 0.0" rpy="0.0 0.0 3.141592653589793"/>
    <parent link="base_link"/>
    <child link="base"/>
  </joint>
  <link name="flange"/>
  <joint name="wrist_3-flange" type="fixed">
    <origin xyz="0.0 0.0 0.0" rpy="0.0 -1.5707963267948966 -1.5707963267948966"/>
    <parent link="wrist_3_link"/>
    <child link="flange"/>
  </joint>
  <link name="tool0"/>
  <joint name="flange-tool0" type="fixed">
    <origin xyz="0.0 0.0 0.0" rpy="1.5707963267948966 0.0 1.5707963267948966"/>
    <parent link="flange"/>
    <child link="tool0"/>
  </joint>
  <gazebo reference="shoulder_link">
    <selfCollide>true</selfCollide>
  </gazebo>
  <gazebo reference="upper_arm_link">
    <selfCollide>true</selfCollide>
  </gazebo>
  <gazebo reference="forearm_link">
    <selfCollide>true</selfCollide>
  </gazebo>
  <gazebo reference="wrist_1_link">
    <selfCollide>true</selfCollide>
  </gazebo>
  <gazebo reference="wrist_3_link">
    <selfCollide>true</selfCollide>
  </gazebo>
  <gazebo reference="wrist_2_link">
    <selfCollide>true</selfCollide>
  </gazebo>
  <gazebo reference="ee_link">
    <selfCollide>true</selfCollide>
  </gazebo>
  <gazebo>
    <plugin filename="libgazebo_ros_control.so" name="ros_control">
    </plugin>
  </gazebo>
  <joint name="moving_base_to_ur5" type="fixed">
    <origin xyz="-0.8520002989717641 -0.12279492296939515 0.3974796675291211" rpy="-0.09152001902158226 -0.002885792435245281 0.8191108336480117"/>
    <parent link="base_link_mb"/>
    <child link="base_link"/>
  </joint>
  <joint name="rgbd_hand_joint" type="fixed">
    <origin xyz="0.0 0.0 -0.02" rpy="0.0 0.0 0.0"/>
    <parent link="flange"/>
    <child link="rgbd_hand_bottom_screw_frame"/>
  </joint>
  <link name="rgbd_hand_bottom_screw_frame"/>
  <joint name="rgbd_hand_link_joint" type="fixed">
    <origin xyz="0.007500000000000001 0.0 0.021150000000000002" rpy="0.0 0.0 0.0"/>
    <parent link="rgbd_hand_bottom_screw_frame"/>
    <child link="rgbd_hand_link"/>
  </joint>
  <link name="rgbd_hand_link">
    <inertial>
      <origin xyz="0.0 0.0 0.0" rpy="0 0 0"/>
      <mass value="0.095"/>
      <inertia ixx="4.4e-05" ixy="0.0" ixz="0.0" iyy="2.7e-05" iyz="0.0" izz="2.7e-05"/>
    </inertial>
    <visual>
      <origin xyz="0.0045 0.0 0.009000000000000001" rpy="1.5707963267948966 0.0 1.5707963267948966"/>
      <geometry>
        <mesh filename="package://realsense2_description/meshes/l515.dae"/>
      </geometry>
    </visual>
    <collision>
      <origin xyz="-0.0085 0.0 0.009000000000000001" rpy="1.5707963267948966 0.0 1.5707963267948966"/>
      <geometry>
        <cylinder radius="0.0305" length="0.026"/>
      </geometry>
    </collision>
  </link>
  <joint name="rgbd_hand_lower_mount_joint" type="fixed">
    <origin xyz="-0.013999999999999999 0.0 0.01015" rpy="0.0 0.0 0.0"/>
    <parent link="rgbd_hand_bottom_screw_frame"/>
    <child link="rgbd_hand_lower_mount"/>
  </joint>
  <link name="rgbd_hand_lower_mount"/>
  <joint name="rgbd_hand_upper_mount_joint" type="fixed">
    <origin xyz="-0.013999999999999999 0.0 0.05015" rpy="0.0 0.0 0.0"/>
    <parent link="rgbd_hand_bottom_screw_frame"/>
    <child link="rgbd_hand_upper_mount"/>
  </joint>
  <link name="rgbd_hand_upper_mount"/>
  <joint name="rgbd_hand_depth_joint" type="fixed">
    <origin xyz="0.0 0.0 0.0" rpy="0.0 0.0 0.0"/>
    <parent link="rgbd_hand_link"/>
    <child link="rgbd_hand_depth_frame"/>
  </joint>
  <link name="rgbd_hand_depth_frame"/>
  <joint name="rgbd_hand_depth_optical_joint" type="fixed">
    <origin xyz="0.0 0.0 0.0" rpy="-1.5707963267948966 0.0 -1.5707963267948966"/>
    <parent link="rgbd_hand_depth_frame"/>
    <child link="rgbd_hand_depth_optical_frame"/>
  </joint>
  <link name="rgbd_hand_depth_optical_frame"/>
  <joint name="rgbd_hand_infra_joint" type="fixed">
    <origin xyz="0.0 0.0 0.0" rpy="0.0 0.0 0.0"/>
    <parent link="rgbd_hand_link"/>
    <child link="rgbd_hand_infra_frame"/>
  </joint>
  <link name="rgbd_hand_infra_frame"/>
  <joint name="rgbd_hand_infra_optical_joint" type="fixed">
    <origin xyz="0.0 0.0 0.0" rpy="-1.5707963267948966 0.0 -1.5707963267948966"/>
    <parent link="rgbd_hand_infra_frame"/>
    <child link="rgbd_hand_infra_optical_frame"/>
  </joint>
  <link name="rgbd_hand_infra_optical_frame"/>
  <joint name="rgbd_hand_color_joint" type="fixed">
    <origin xyz="0.6871970198884385 0.12996645291937317 0.39571018683490666" rpy="-0.5699416838708846 0.14395220215263646 -0.09562433799646684"/>
    <parent link="rgbd_hand_link"/>
    <child link="rgbd_hand_color_frame"/>
  </joint>
  <link name="rgbd_hand_color_frame"/>
  <joint name="rgbd_hand_color_optical_joint" type="fixed">
    <origin xyz="0.0 0.0 0.0" rpy="-1.5707963267948966 0.0 -1.5707963267948966"/>
    <parent link="rgbd_hand_color_frame"/>
    <child link="rgbd_hand_color_optical_frame"/>
  </joint>
  <link name="rgbd_hand_color_optical_frame"/>
  <link name="rgbd_hand_gyro_frame"/>
  <link name="rgbd_hand_gyro_optical_frame"/>
  <link name="rgbd_hand_accel_frame"/>
  <link name="rgbd_hand_accel_optical_frame"/>
  <joint name="rgbd_hand_gyro_joint" type="fixed">
    <origin xyz="-0.00410137791186571 -0.0129784867167473 0.00256138201802969" rpy="-0.006161012 0.020193459 0.016301375"/>
    <parent link="rgbd_hand_color_frame"/>
    <child link="rgbd_hand_gyro_frame"/>
  </joint>
  <joint name="rgbd_hand_gyro_optical_joint" type="fixed">
    <origin xyz="0.0 0.0 0.0" rpy="-1.5707963267948966 0.0 -1.5707963267948966"/>
    <parent link="rgbd_hand_gyro_frame"/>
    <child link="rgbd_hand_gyro_optical_frame"/>
  </joint>
  <joint name="rgbd_hand_accel_joint" type="fixed">
    <origin xyz="-0.00410137791186571 -0.0129784867167473 0.00256138201802969" rpy="-0.006161012 0.020193459 0.016301375"/>
    <parent link="rgbd_hand_color_frame"/>
    <child link="rgbd_hand_accel_frame"/>
  </joint>
  <joint name="rgbd_hand_accel_optical_joint" type="fixed">
    <origin xyz="0.0 0.0 0.0" rpy="-1.5707963267948966 0.0 -1.5707963267948966"/>
    <parent link="rgbd_hand_accel_frame"/>
    <child link="rgbd_hand_accel_optical_frame"/>
  </joint>
  <link name="pattern_link">
    <origin xyz="0 0 0" rpy="0 0 0"/>
    <visual name="pattern_1_visual">
      <origin xyz="0 0 0" rpy="0 0 0"/>
      <geometry>
        <mesh filename="package://atom_worlds/pattern/models/charuco_800x600_5x5_100/charuco_800x600_5x5_100.dae"/>
      </geometry>
    </visual>
  </link>
  <joint name="world-pattern_link" type="fixed">
    <origin xyz="2.6038062558095283 -0.711041255883697 0.9662541590342425" rpy="1.1294426753503517 1.0300991339225574 1.1282630443481336"/>
    <parent link="world"/>
    <child link="pattern_link"/>
  </joint>
</robot>